{
  "questions": [
    {
      "question_text": "Did Mercia Asset Management PLC mention any mergers or acquisitions in the annual report?",
      "kind": "boolean",
      "value": null,
      "references": [],
      "error": "ValueError: No report found with 'Mercia Asset Management PLC' company name.",
      "answer_details": {
        "$ref": "#/answer_details/0"
      }
    },
    {
      "question_text": "According to the annual report, what is the Operating margin (%) for Tradition (within the last period or at the end of the last period)? If data is not available, return 'N/A'.",
      "kind": "number",
      "value": null,
      "references": [],
      "error": "ValueError: No report found with 'Tradition' company name.",
      "answer_details": {
        "$ref": "#/answer_details/1"
      }
    },
    {
      "question_text": "Did TSX_Y announce a share buyback plan in the annual report?",
      "kind": "boolean",
      "value": null,
      "references": [],
      "error": "RateLimitError: Error code: 429 - {'error': {'message': 'You exceeded your current quota, please check your plan and billing details. For more information on this error, read the docs: https://platform.openai.com/docs/guides/error-codes/api-errors.', 'type': 'insufficient_quota', 'param': None, 'code': 'insufficient_quota'}}",
      "answer_details": {
        "$ref": "#/answer_details/2"
      }
    },
    {
      "question_text": "What was the largest single spending of CrossFirst Bank on executive compensation in USD?",
      "kind": "name",
      "value": null,
      "references": [],
      "error": "ValueError: No report found with 'CrossFirst Bank' company name.",
      "answer_details": {
        "$ref": "#/answer_details/3"
      }
    },
    {
      "question_text": "Did Holley Inc. mention any mergers or acquisitions in the annual report?",
      "kind": "boolean",
      "value": null,
      "references": [],
      "error": "RateLimitError: Error code: 429 - {'error': {'message': 'You exceeded your current quota, please check your plan and billing details. For more information on this error, read the docs: https://platform.openai.com/docs/guides/error-codes/api-errors.', 'type': 'insufficient_quota', 'param': None, 'code': 'insufficient_quota'}}",
      "answer_details": {
        "$ref": "#/answer_details/4"
      }
    }
  ],
  "answer_details": [
    {
      "error_traceback": "Traceback (most recent call last):\n  File \"/root/RAG_Challenge_Reproducibility/src/questions_processing.py\", line 278, in _process_single_question\n    answer_dict = self.process_question(question_text, schema)\n                  ^^^^^^^^^^^^^^^^^^^^^^^^^^^^^^^^^^^^^^^^^^^^\n  File \"/root/RAG_Challenge_Reproducibility/src/questions_processing.py\", line 195, in process_question\n    answer_dict = self.get_answer_for_company(company_name=company_name, question=question, schema=schema)\n                  ^^^^^^^^^^^^^^^^^^^^^^^^^^^^^^^^^^^^^^^^^^^^^^^^^^^^^^^^^^^^^^^^^^^^^^^^^^^^^^^^^^^^^^^^\n  File \"/root/RAG_Challenge_Reproducibility/src/questions_processing.py\", line 137, in get_answer_for_company\n    retrieval_results = retriever.retrieve_by_company_name(\n                        ^^^^^^^^^^^^^^^^^^^^^^^^^^^^^^^^^^^\n  File \"/root/RAG_Challenge_Reproducibility/src/retrieval.py\", line 167, in retrieve_by_company_name\n    raise ValueError(f\"No report found with '{company_name}' company name.\")\nValueError: No report found with 'Mercia Asset Management PLC' company name.\n",
      "self": "#/answer_details/0"
    },
    {
      "error_traceback": "Traceback (most recent call last):\n  File \"/root/RAG_Challenge_Reproducibility/src/questions_processing.py\", line 278, in _process_single_question\n    answer_dict = self.process_question(question_text, schema)\n                  ^^^^^^^^^^^^^^^^^^^^^^^^^^^^^^^^^^^^^^^^^^^^\n  File \"/root/RAG_Challenge_Reproducibility/src/questions_processing.py\", line 195, in process_question\n    answer_dict = self.get_answer_for_company(company_name=company_name, question=question, schema=schema)\n                  ^^^^^^^^^^^^^^^^^^^^^^^^^^^^^^^^^^^^^^^^^^^^^^^^^^^^^^^^^^^^^^^^^^^^^^^^^^^^^^^^^^^^^^^^\n  File \"/root/RAG_Challenge_Reproducibility/src/questions_processing.py\", line 137, in get_answer_for_company\n    retrieval_results = retriever.retrieve_by_company_name(\n                        ^^^^^^^^^^^^^^^^^^^^^^^^^^^^^^^^^^^\n  File \"/root/RAG_Challenge_Reproducibility/src/retrieval.py\", line 167, in retrieve_by_company_name\n    raise ValueError(f\"No report found with '{company_name}' company name.\")\nValueError: No report found with 'Tradition' company name.\n",
      "self": "#/answer_details/1"
    },
    {
      "error_traceback": "Traceback (most recent call last):\n  File \"/root/RAG_Challenge_Reproducibility/src/questions_processing.py\", line 278, in _process_single_question\n    answer_dict = self.process_question(question_text, schema)\n                  ^^^^^^^^^^^^^^^^^^^^^^^^^^^^^^^^^^^^^^^^^^^^\n  File \"/root/RAG_Challenge_Reproducibility/src/questions_processing.py\", line 195, in process_question\n    answer_dict = self.get_answer_for_company(company_name=company_name, question=question, schema=schema)\n                  ^^^^^^^^^^^^^^^^^^^^^^^^^^^^^^^^^^^^^^^^^^^^^^^^^^^^^^^^^^^^^^^^^^^^^^^^^^^^^^^^^^^^^^^^\n  File \"/root/RAG_Challenge_Reproducibility/src/questions_processing.py\", line 137, in get_answer_for_company\n    retrieval_results = retriever.retrieve_by_company_name(\n                        ^^^^^^^^^^^^^^^^^^^^^^^^^^^^^^^^^^^\n  File \"/root/RAG_Challenge_Reproducibility/src/retrieval.py\", line 176, in retrieve_by_company_name\n    embedding = self.llm.embeddings.create(\n                ^^^^^^^^^^^^^^^^^^^^^^^^^^^\n  File \"/root/RAG_Challenge_Reproducibility/venv/lib/python3.11/site-packages/openai/resources/embeddings.py\", line 124, in create\n    return self._post(\n           ^^^^^^^^^^^\n  File \"/root/RAG_Challenge_Reproducibility/venv/lib/python3.11/site-packages/openai/_base_client.py\", line 1277, in post\n    return cast(ResponseT, self.request(cast_to, opts, stream=stream, stream_cls=stream_cls))\n                           ^^^^^^^^^^^^^^^^^^^^^^^^^^^^^^^^^^^^^^^^^^^^^^^^^^^^^^^^^^^^^^^^^\n  File \"/root/RAG_Challenge_Reproducibility/venv/lib/python3.11/site-packages/openai/_base_client.py\", line 954, in request\n    return self._request(\n           ^^^^^^^^^^^^^^\n  File \"/root/RAG_Challenge_Reproducibility/venv/lib/python3.11/site-packages/openai/_base_client.py\", line 1043, in _request\n    return self._retry_request(\n           ^^^^^^^^^^^^^^^^^^^^\n  File \"/root/RAG_Challenge_Reproducibility/venv/lib/python3.11/site-packages/openai/_base_client.py\", line 1092, in _retry_request\n    return self._request(\n           ^^^^^^^^^^^^^^\n  File \"/root/RAG_Challenge_Reproducibility/venv/lib/python3.11/site-packages/openai/_base_client.py\", line 1043, in _request\n    return self._retry_request(\n           ^^^^^^^^^^^^^^^^^^^^\n  File \"/root/RAG_Challenge_Reproducibility/venv/lib/python3.11/site-packages/openai/_base_client.py\", line 1092, in _retry_request\n    return self._request(\n           ^^^^^^^^^^^^^^\n  File \"/root/RAG_Challenge_Reproducibility/venv/lib/python3.11/site-packages/openai/_base_client.py\", line 1058, in _request\n    raise self._make_status_error_from_response(err.response) from None\nopenai.RateLimitError: Error code: 429 - {'error': {'message': 'You exceeded your current quota, please check your plan and billing details. For more information on this error, read the docs: https://platform.openai.com/docs/guides/error-codes/api-errors.', 'type': 'insufficient_quota', 'param': None, 'code': 'insufficient_quota'}}\n",
      "self": "#/answer_details/2"
    },
    {
      "error_traceback": "Traceback (most recent call last):\n  File \"/root/RAG_Challenge_Reproducibility/src/questions_processing.py\", line 278, in _process_single_question\n    answer_dict = self.process_question(question_text, schema)\n                  ^^^^^^^^^^^^^^^^^^^^^^^^^^^^^^^^^^^^^^^^^^^^\n  File \"/root/RAG_Challenge_Reproducibility/src/questions_processing.py\", line 195, in process_question\n    answer_dict = self.get_answer_for_company(company_name=company_name, question=question, schema=schema)\n                  ^^^^^^^^^^^^^^^^^^^^^^^^^^^^^^^^^^^^^^^^^^^^^^^^^^^^^^^^^^^^^^^^^^^^^^^^^^^^^^^^^^^^^^^^\n  File \"/root/RAG_Challenge_Reproducibility/src/questions_processing.py\", line 137, in get_answer_for_company\n    retrieval_results = retriever.retrieve_by_company_name(\n                        ^^^^^^^^^^^^^^^^^^^^^^^^^^^^^^^^^^^\n  File \"/root/RAG_Challenge_Reproducibility/src/retrieval.py\", line 167, in retrieve_by_company_name\n    raise ValueError(f\"No report found with '{company_name}' company name.\")\nValueError: No report found with 'CrossFirst Bank' company name.\n",
      "self": "#/answer_details/3"
    },
    {
      "error_traceback": "Traceback (most recent call last):\n  File \"/root/RAG_Challenge_Reproducibility/src/questions_processing.py\", line 278, in _process_single_question\n    answer_dict = self.process_question(question_text, schema)\n                  ^^^^^^^^^^^^^^^^^^^^^^^^^^^^^^^^^^^^^^^^^^^^\n  File \"/root/RAG_Challenge_Reproducibility/src/questions_processing.py\", line 195, in process_question\n    answer_dict = self.get_answer_for_company(company_name=company_name, question=question, schema=schema)\n                  ^^^^^^^^^^^^^^^^^^^^^^^^^^^^^^^^^^^^^^^^^^^^^^^^^^^^^^^^^^^^^^^^^^^^^^^^^^^^^^^^^^^^^^^^\n  File \"/root/RAG_Challenge_Reproducibility/src/questions_processing.py\", line 137, in get_answer_for_company\n    retrieval_results = retriever.retrieve_by_company_name(\n                        ^^^^^^^^^^^^^^^^^^^^^^^^^^^^^^^^^^^\n  File \"/root/RAG_Challenge_Reproducibility/src/retrieval.py\", line 176, in retrieve_by_company_name\n    embedding = self.llm.embeddings.create(\n                ^^^^^^^^^^^^^^^^^^^^^^^^^^^\n  File \"/root/RAG_Challenge_Reproducibility/venv/lib/python3.11/site-packages/openai/resources/embeddings.py\", line 124, in create\n    return self._post(\n           ^^^^^^^^^^^\n  File \"/root/RAG_Challenge_Reproducibility/venv/lib/python3.11/site-packages/openai/_base_client.py\", line 1277, in post\n    return cast(ResponseT, self.request(cast_to, opts, stream=stream, stream_cls=stream_cls))\n                           ^^^^^^^^^^^^^^^^^^^^^^^^^^^^^^^^^^^^^^^^^^^^^^^^^^^^^^^^^^^^^^^^^\n  File \"/root/RAG_Challenge_Reproducibility/venv/lib/python3.11/site-packages/openai/_base_client.py\", line 954, in request\n    return self._request(\n           ^^^^^^^^^^^^^^\n  File \"/root/RAG_Challenge_Reproducibility/venv/lib/python3.11/site-packages/openai/_base_client.py\", line 1043, in _request\n    return self._retry_request(\n           ^^^^^^^^^^^^^^^^^^^^\n  File \"/root/RAG_Challenge_Reproducibility/venv/lib/python3.11/site-packages/openai/_base_client.py\", line 1092, in _retry_request\n    return self._request(\n           ^^^^^^^^^^^^^^\n  File \"/root/RAG_Challenge_Reproducibility/venv/lib/python3.11/site-packages/openai/_base_client.py\", line 1043, in _request\n    return self._retry_request(\n           ^^^^^^^^^^^^^^^^^^^^\n  File \"/root/RAG_Challenge_Reproducibility/venv/lib/python3.11/site-packages/openai/_base_client.py\", line 1092, in _retry_request\n    return self._request(\n           ^^^^^^^^^^^^^^\n  File \"/root/RAG_Challenge_Reproducibility/venv/lib/python3.11/site-packages/openai/_base_client.py\", line 1058, in _request\n    raise self._make_status_error_from_response(err.response) from None\nopenai.RateLimitError: Error code: 429 - {'error': {'message': 'You exceeded your current quota, please check your plan and billing details. For more information on this error, read the docs: https://platform.openai.com/docs/guides/error-codes/api-errors.', 'type': 'insufficient_quota', 'param': None, 'code': 'insufficient_quota'}}\n",
      "self": "#/answer_details/4"
    }
  ],
  "statistics": {
    "total_questions": 5,
    "error_count": 5,
    "na_count": 0,
    "success_count": 0
  }
}